Workbook

Sheet Sammendrag
A1: BADSTUE MED SMØREBOD + OVERBYGG — MATERIALBEREGNING
A2: Byggherre: Trond Dahl
A3: Dato: 2026-04-17
A4: Referanse: Tegninger rev. H
A6: Nøkkeltall bygg
A7: Utvendig bredde × dybde | B7: 4660 × 2460 mm
A8: Smørebod innvendig | B8: 2500 × 2200 mm (5,5 m²)
A9: Badstue innvendig | B9: 1800 × 2200 mm (3,96 m²)
A10: Innv. takhøyde front/bak | B10: 2400 / 2010 mm
A11: Takvinkel | B11: 10°, høyest foran
A12: Overbygg mot hytta | B12: 3000 × 2460 mm (åpent, uten post)
A13: Fundament | B13: 6 støpte sokler under badstuebygget
A14: Snølast dimensjonert | B14: 450 kg/m² (fjell)
A16: Kostnadssammendrag pr. kategori
A17: Kategori | B17: Antall varelinjer | C17: Sum kr (eks. mva) | D17: Merknad
A18: 1. Fundament | B18: =COUNTIF(Materialliste!C3:C79,A18) -> 4 | C18: =SUMIF(Materialliste!C3:C79,A18,Materialliste!J3:J79) -> 0 | D18: Har allerede — gjenbrukes (kostnad 0)
A19: 2. Bjelkelag og gulv | B19: =COUNTIF(Materialliste!C3:C79,A19) -> 9 | C19: =SUMIF(Materialliste!C3:C79,A19,Materialliste!J3:J79) -> 12898 | D19: Sviller, gulvbjelker, radonduk, undergulv, gulvbord
A20: 3. Vegger (bindingsverk) | B20: =COUNTIF(Materialliste!C3:C79,A20) -> 9 | C20: =SUMIF(Materialliste!C3:C79,A20,Materialliste!J3:J79) -> 8777 | D20: Stendere 48×98, sviller, mellomvegg, overbygg nordvegg
A21: 4. Tak (bærende) | B21: =COUNTIF(Materialliste!C3:C79,A21) -> 5 | C21: =SUMIF(Materialliste!C3:C79,A21,Materialliste!J3:J79) -> 7733 | D21: Takbjelker 48×148, sydbjelke 2×48×198, vindskier
A22: 5. Tak (tekking og lufting) | B22: =COUNTIF(Materialliste!C3:C79,A22) -> 8 | C22: =SUMIF(Materialliste!C3:C79,A22,Materialliste!J3:J79) -> 19390 | D22: Taktro, sløyfer, undertaksduk, shingel
A23: 6. Utv. kledning og lufting | B23: =COUNTIF(Materialliste!C3:C79,A23) -> 6 | C23: =SUMIF(Materialliste!C3:C79,A23,Materialliste!J3:J79) -> 36864 | D23: Vindsperre, klimaspalte-lekter, stående tømmermannspanel
A24: 7. Isolasjon | B24: =COUNTIF(Materialliste!C3:C79,A24) -> 4 | C24: =SUMIF(Materialliste!C3:C79,A24,Materialliste!J3:J79) -> 11006 | D24: Mineralull vegger, tak, gulv
A25: 8. Dampsperre og innvendig panel | B25: =COUNTIF(Materialliste!C3:C79,A25) -> 5 | C25: =SUMIF(Materialliste!C3:C79,A25,Materialliste!J3:J79) -> 21326 | D25: Alu-folie, PE-folie, osp/furu panel
A26: 9. Vinduer og dører | B26: =COUNTIF(Materialliste!C3:C79,A26) -> 6 | C26: =SUMIF(Materialliste!C3:C79,A26,Materialliste!J3:J79) -> 1990 | D26: Har vinduer/dører — kun monteringsskum + gerikter gjenstår
A27: 10. Beslag, skruer og diverse | B27: =COUNTIF(Materialliste!C3:C79,A27) -> 11 | C27: =SUMIF(Materialliste!C3:C79,A27,Materialliste!J3:J79) -> 13059 | D27: Vinkelbeslag, spiker/skruer, tetting, beslag mot hytta
A28: 11. Badstueinnredning | B28: =COUNTIF(Materialliste!C3:C79,A28) -> 10 | C28: =SUMIF(Materialliste!C3:C79,A28,Materialliste!J3:J79) -> 21315 | D28: Benker, ovn (separat), vifter, termometer
A29: TOTAL (eks. mva) | C29: =SUM(C18:C28) -> 154358
A30: MVA 25% | C30: =C29*0.25 -> 38589.5
A31: TOTAL (inkl. mva) | C31: =C29+C30 -> 192947.5
A34: Notater:
A35: • Priser er veiledende estimater (norske priser Q1 2026). Sjekk faktiske priser hos lokal byggevarehandel.
A36: • Mengder inkluderer typisk 10-15 % kapp/spill der relevant.
A37: • Badstueovn (anbefalt 11 kW el. eller 13 kW vedfyrt) er ført opp, men bør bestilles separat med tilpasning til eget valg.
A38: • Eksisterende terrasse gjenbrukes som gulv i overbygget — ikke inkludert.
A39: • Grunnarbeid (graving, pukk, telesikring) er ikke med — legges til etter forhold på tomt.
A40: • Rigg og frakt utelatt fra sammendraget.

Sheet Prosjektfaser
A1: PROSJEKT I TO TRINN
A2: Trinn 1: Hele bygget reises og lukkes, smørebod ferdig innredet. Badstuerommet står som ferdig isolert,
A3: lukket rårom — klart til å gjøres om til badstue senere (trinn 2).
A4: Trinn 2: Innredning av selve badstuerommet — dampsperre, osppanel, benker, ovn, gulv og utstyr.
A6: TRINN 2 — innredning av badstuerommet (utsettes)
A7: Vare | B7: Hører til | C7: Kostnad (kr) | D7: Merknad
A8: Sklisikkert badstuegulv (fliser/membran/sluk) | B8: Gulv | C8: =Materialliste!J15 -> 3000 | D8: Legges når rommet innredes
A9: Aluminiumsfolie dampsperre (badstue) | B9: Vegg/tak | C9: =Materialliste!J48 -> 2508 | D9: Monteres med osppanelet
A10: Osp-panel 15×70 (badstue innv. vegg + tak) | B10: Overflate | C10: =Materialliste!J51 -> 10626 | D10: Varmebestandig innvendig kledning
A11: Benkestolper / bjelker 48×98 osp | B11: Benker | C11: =Materialliste!J70 -> 2090
A12: Benketoppbord 28×90 osp | B12: Benker | C12: =Materialliste!J71 -> 5610 | D12: Sittflater m/ luftespalte
A13: Badstueovn (11 kW el. / 13 kW ved) | B13: Utstyr | C13: =Materialliste!J72 -> 9000 | D13: Anbefalt 11 kW — se ark Beregninger
A14: Varmeskjerm bak ovn | B14: Utstyr | C14: =Materialliste!J73 -> 850 | D14: Ved kort avstand til vegg
A15: Ventil tilluft 60 mm | B15: Ventilasjon | C15: =Materialliste!J74 -> 220 | D15: Nede ved ovn
A16: Ventil avtrekk 100 mm m/ trekk | B16: Ventilasjon | C16: =Materialliste!J75 -> 320 | D16: Diagonalt motsatt hjørne
A17: Termometer / hygrometer | B17: Utstyr | C17: =Materialliste!J76 -> 450
A18: Belysning IP-badstue | B18: El | C18: =Materialliste!J77 -> 950 | D18: LED m/ trafo
A19: Badstuestein | B19: Utstyr | C19: =Materialliste!J78 -> 625 | D19: 20–30 kg olivin/peridotitt
A20: Gulvrist badstue (tre) | B20: Gulv | C20: =Materialliste!J79 -> 1200 | D20: Osp eller sedertre
A21: SUM TRINN 2 | C21: =SUM(C8:C20) -> 37449
A23: KOSTNADSOVERSIKT — TO VARIANTER
A24: Variant | B24: Eks. mva | C24: Inkl. mva 25 % | D24: Innhold
A25: VARIANT A — Helt ferdig (alt på én gang) | B25: =Materialliste!J80 -> 154358 | C25: =Materialliste!J80*1.25 -> 192947.5 | D25: Komplett bygg + smørebod + ferdig innredet badstue
A26: VARIANT B — Trinn 1 (badstuerom ikke innredet) | B26: =Materialliste!J80-C21 -> 116909 | C26: =(Materialliste!J80-C21)*1.25 -> 146136.25 | D26: Komplett, lukket og isolert bygg. Smørebod ferdig. Badstuerom = rårom
A27: + Trinn 2 (badstuerom innredes senere) | B27: =C21 -> 37449 | C27: =C21*1.25 -> 46811.25 | D27: Dampsperre, osppanel, benker, ovn, gulv, ventiler, utstyr
A29: Notater:
A30: • I trinn 1 ER badstuerommet isolert (mineralull i vegg og tak) og lukket — kun overflater og utstyr gjenstår.
A31: • Dampsperre (alu-folie) monteres sammen med ospanelet i trinn 2 — derfor utsatt.
A32: • Smørebod/relax-rommet blir helt ferdig i trinn 1 og kan brukes umiddelbart.
A33: • Trinn 2 kan gjøres når som helst senere uten inngrep i bærende konstruksjon eller tak.
A34: • Beløpene oppdateres automatisk hvis du endrer priser/mengder i arket "Materialliste".
A35: • Tallene gjelder standardvalg. Budsjettvalg (ark "Budsjettvariant") kan kombineres med begge trinn.

Sheet Materialliste
A1: DETALJERT MATERIALLISTE
A2: Nr | B2: Vare / beskrivelse | C2: Kategori | D2: Dimensjon / spesifikasjon | E2: Enhet | F2: Netto mengde | G2: Kapp/spill % | H2: Bestilles | I2: Enhetspris (kr) | J2: Sum (kr) | K2: Kommentar
A3: 1 | B3: Betong C25/30 (ferdigbl.) | C3: 1. Fundament | D3: Sokler 6 stk: søyle 250×250×1800 + plate 500×500×200 | E3: m³ | F3: 1 | G3: 10 | H3: =ROUND(F3*(1+G3/100),1) -> 1.1 | I3: 0 | J3: =ROUND(H3*I3,0) -> 0 | K3: HAR ALLEREDE — gjenbruk. 6 sokler totalt
A4: 2 | B4: Armering Ø12 kamstål | C4: 1. Fundament | D4: Lengdestenger i søyle + krysspor i plate | E4: kg | F4: 30 | G4: 10 | H4: =ROUND(F4*(1+G4/100),1) -> 33 | I4: 0 | J4: =ROUND(H4*I4,0) -> 0 | K4: HAR ALLEREDE — gjenbruk. ~5 kg per sokkel
A5: 3 | B5: Fundamentbolt M16×400 m/ mutter+skive | C5: 1. Fundament | D5: Galvanisert for svillefeste | E5: stk | F5: 12 | G5: 0 | H5: =ROUND(F5*(1+G5/100),1) -> 12 | I5: 0 | J5: =ROUND(H5*I5,0) -> 0 | K5: HAR ALLEREDE — gjenbruk. 2 per sokkel
A6: 4 | B6: Sokkelbånd / fuktsperre | C6: 1. Fundament | D6: 14,24 m perimeter + 5 cm overlapp | E6: m | F6: 16 | G6: 5 | H6: =ROUND(F6*(1+G6/100),1) -> 16.8 | I6: 0 | J6: =ROUND(H6*I6,0) -> 0 | K6: HAR ALLEREDE — gjenbruk. EPDM eller pvc
A7: 5 | B7: Svill 48×148 trykkimpregnert | C7: 2. Bjelkelag og gulv | D7: Under yttervegg | E7: lm | F7: 14.24 | G7: 10 | H7: =ROUND(F7*(1+G7/100),1) -> 15.7 | I7: 65 | J7: =ROUND(H7*I7,0) -> 1021 | K7: Ytterveggs svill
A8: 6 | B8: Svill 48×98 trykkimpregnert | C8: 2. Bjelkelag og gulv | D8: Under mellomvegg | E8: lm | F8: 2.46 | G8: 10 | H8: =ROUND(F8*(1+G8/100),1) -> 2.7 | I8: 45 | J8: =ROUND(H8*I8,0) -> 122 | K8: Mellomvegg
A9: 7 | B9: Gulvbjelker 48×148 C24 | C9: 2. Bjelkelag og gulv | D9: c/c 600, spenn 2,46 m | E9: lm | F9: 22 | G9: 10 | H9: =ROUND(F9*(1+G9/100),1) -> 24.2 | I9: 65 | J9: =ROUND(H9*I9,0) -> 1573 | K9: 9 stk á 2,5 m
A10: 8 | B10: Kantbjelker 48×148 C24 | C10: 2. Bjelkelag og gulv | D10: Rundt bjelkelag | E10: lm | F10: 15 | G10: 10 | H10: =ROUND(F10*(1+G10/100),1) -> 16.5 | I10: 65 | J10: =ROUND(H10*I10,0) -> 1073 | K10: Perimeter
A11: 9 | B11: Radonsperre / bunnmembran | C11: 2. Bjelkelag og gulv | D11: Under gulv, radonpapp | E11: m² | F11: 12 | G11: 15 | H11: =ROUND(F11*(1+G11/100),1) -> 13.8 | I11: 0 | J11: =ROUND(H11*I11,0) -> 0 | K11: UTGÅR — bygget står på 6 pilarer med ventilert kryperom (radon luftes bort)
A12: 10 | B12: Undergulv sponplate 22 mm P5 | C12: 2. Bjelkelag og gulv | D12: Plate 600×2400 | E12: m² | F12: 12 | G12: 10 | H12: =ROUND(F12*(1+G12/100),1) -> 13.2 | I12: 180 | J12: =ROUND(H12*I12,0) -> 2376 | K12: 3 stk
A13: 11 | B13: Vindsperre / vindtetting ramme | C13: 2. Bjelkelag og gulv | D13: Duk mellom bjelkelag og yttervegg-svill | E13: lm | F13: 14.24 | G13: 10 | H13: =ROUND(F13*(1+G13/100),1) -> 15.7 | I13: 40 | J13: =ROUND(H13*I13,0) -> 628
A14: 12 | B14: Gulvbord 28×120 furu (smørebod) | C14: 2. Bjelkelag og gulv | D14: 2,5 × 2,2 = 5,5 m² | E14: m² | F14: 6 | G14: 15 | H14: =ROUND(F14*(1+G14/100),1) -> 6.9 | I14: 450 | J14: =ROUND(H14*I14,0) -> 3105 | K14: Høvlet furugulv
A15: 13 | B15: Sklisikkert badstuegulv (fliser/betong) | C15: 2. Bjelkelag og gulv | D15: Ca 4 m² inkl sluk | E15: m² | F15: 4.5 | G15: 10 | H15: =ROUND(F15*(1+G15/100),1) -> 5 | I15: 600 | J15: =ROUND(H15*I15,0) -> 3000 | K15: Fliser + membran + sluk
A16: 14 | B16: Stendere 48×98 C24 (yttervegg) | C16: 3. Vegger (bindingsverk) | D16: c/c 600, høyde 2,2 m avg | E16: lm | F16: 66 | G16: 10 | H16: =ROUND(F16*(1+G16/100),1) -> 72.6 | I16: 45 | J16: =ROUND(H16*I16,0) -> 3267 | K16: ~30 stendere
A17: 15 | B17: Topp-/bunnsvill 48×98 (yttervegg) | C17: 3. Vegger (bindingsverk) | D17: Perimeter × 2 svill | E17: lm | F17: 29 | G17: 10 | H17: =ROUND(F17*(1+G17/100),1) -> 31.9 | I17: 45 | J17: =ROUND(H17*I17,0) -> 1436 | K17: Topp + bunn svill
A18: 16 | B18: Topp-topptømmer dobbel 48×98 | C18: 3. Vegger (bindingsverk) | D18: Yttervegg topp | E18: lm | F18: 14.24 | G18: 10 | H18: =ROUND(F18*(1+G18/100),1) -> 15.7 | I18: 45 | J18: =ROUND(H18*I18,0) -> 707 | K18: Ekstra svill for takbjelker
A19: 17 | B19: Stendere 48×98 mellomvegg | C19: 3. Vegger (bindingsverk) | D19: 2,46 m bred, c/c 600 | E19: lm | F19: 11 | G19: 10 | H19: =ROUND(F19*(1+G19/100),1) -> 12.1 | I19: 45 | J19: =ROUND(H19*I19,0) -> 545 | K19: 5 stendere
A20: 18 | B20: Sviller mellomvegg 48×98 | C20: 3. Vegger (bindingsverk) | D20: Topp + bunn | E20: lm | F20: 5 | G20: 10 | H20: =ROUND(F20*(1+G20/100),1) -> 5.5 | I20: 45 | J20: =ROUND(H20*I20,0) -> 248
A21: 19 | B21: Dørramme forsterking 48×98 | C21: 3. Vegger (bindingsverk) | D21: Rundt dører og vinduer | E21: lm | F21: 12 | G21: 10 | H21: =ROUND(F21*(1+G21/100),1) -> 13.2 | I21: 45 | J21: =ROUND(H21*I21,0) -> 594 | K21: Forsterking åpninger
A22: 20 | B22: Stendere 48×98 overbygg nordvegg | C22: 3. Vegger (bindingsverk) | D22: c/c 600, 3 m vegg | E22: lm | F22: 14 | G22: 10 | H22: =ROUND(F22*(1+G22/100),1) -> 15.4 | I22: 45 | J22: =ROUND(H22*I22,0) -> 693 | K22: 6 stendere
A23: 21 | B23: Sviller 48×98 overbygg nordvegg | C23: 3. Vegger (bindingsverk) | D23: Topp + bunn | E23: lm | F23: 6 | G23: 10 | H23: =ROUND(F23*(1+G23/100),1) -> 6.6 | I23: 45 | J23: =ROUND(H23*I23,0) -> 297
A24: 22 | B24: Vindavstivning / diagonalavstivning | C24: 3. Vegger (bindingsverk) | D24: 22×98 skråstag el. stålbånd | E24: lm | F24: 30 | G24: 10 | H24: =ROUND(F24*(1+G24/100),1) -> 33 | I24: 30 | J24: =ROUND(H24*I24,0) -> 990
A25: 23 | B25: Takbjelker 48×148 C24 | C25: 4. Tak (bærende) | D25: c/c 500, lengde 3,06 m inkl utstikk | E25: lm | F25: 50 | G25: 10 | H25: =ROUND(F25*(1+G25/100),1) -> 55 | I25: 75 | J25: =ROUND(H25*I25,0) -> 4125 | K25: 16 bjelker over hele bygget + overbygg
A26: 24 | B26: Sydbjelke 2×48×198 C24 (koblet) | C26: 4. Tak (bærende) | D26: Overbygg fritt spenn 3 m | E26: lm | F26: 7 | G26: 5 | H26: =ROUND(F26*(1+G26/100),1) -> 7.4 | I26: 110 | J26: =ROUND(H26*I26,0) -> 814 | K26: 2 stk × 3,3 m
A27: 25 | B27: Forsterkning over vindu/dør 48×148 | C27: 4. Tak (bærende) | D27: Overligger over åpninger | E27: lm | F27: 8 | G27: 10 | H27: =ROUND(F27*(1+G27/100),1) -> 8.8 | I27: 75 | J27: =ROUND(H27*I27,0) -> 660
A28: 26 | B28: Vindskier 25×200 furu | C28: 4. Tak (bærende) | D28: Øst-gavl (vest mot hytta med beslag) | E28: lm | F28: 8 | G28: 10 | H28: =ROUND(F28*(1+G28/100),1) -> 8.8 | I28: 85 | J28: =ROUND(H28*I28,0) -> 748 | K28: Bredere vindskier
A29: 27 | B29: Gavlbord 22×170 | C29: 4. Tak (bærende) | D29: Takutstikk foran/bak | E29: lm | F29: 18 | G29: 10 | H29: =ROUND(F29*(1+G29/100),1) -> 19.8 | I29: 70 | J29: =ROUND(H29*I29,0) -> 1386 | K29: 2 × 7,66 m + litt ekstra
A30: 28 | B30: Taktro 22×120 furu | C30: 5. Tak (tekking og lufting) | D30: På sløyfer, underlag for shingel | E30: m² | F30: 24 | G30: 10 | H30: =ROUND(F30*(1+G30/100),1) -> 26.4 | I30: 320 | J30: =ROUND(H30*I30,0) -> 8448 | K30: ~20 m² takareal + utstikk
A31: 29 | B31: Sløyfer 23×48 C24 | C31: 5. Tak (tekking og lufting) | D31: Langs takbjelker, 50 mm luftespalte | E31: lm | F31: 50 | G31: 10 | H31: =ROUND(F31*(1+G31/100),1) -> 55 | I31: 22 | J31: =ROUND(H31*I31,0) -> 1210 | K31: Over undertaksduk
A32: 30 | B32: Undertaksduk (diffusjonsåpen) | C32: 5. Tak (tekking og lufting) | D32: f.eks. Delta-Vent eller tilsvarende | E32: m² | F32: 25 | G32: 15 | H32: =ROUND(F32*(1+G32/100),1) -> 28.8 | I32: 65 | J32: =ROUND(H32*I32,0) -> 1872 | K32: 1 rull 75 m² dekker
A33: 31 | B33: Bitumen underlagspapp (shingel) | C33: 5. Tak (tekking og lufting) | D33: Selvklebende, på taktro | E33: m² | F33: 24 | G33: 10 | H33: =ROUND(F33*(1+G33/100),1) -> 26.4 | I33: 85 | J33: =ROUND(H33*I33,0) -> 2244 | K33: 1-2 ruller
A34: 32 | B34: Asfalt-shingel | C34: 5. Tak (tekking og lufting) | D34: Pakke dekker 3 m² ferdig | E34: pakke | F34: 9 | G34: 0 | H34: =ROUND(F34*(1+G34/100),1) -> 9 | I34: 450 | J34: =ROUND(H34*I34,0) -> 4050 | K34: ~26 m² inkl kapp
A35: 33 | B35: Shingel-spiker galvanisert | C35: 5. Tak (tekking og lufting) | D35: 25×2,8 mm | E35: kg | F35: 1 | G35: 0 | H35: =ROUND(F35*(1+G35/100),1) -> 1 | I35: 180 | J35: =ROUND(H35*I35,0) -> 180
A36: 34 | B36: Mønebord/overkant takkant | C36: 5. Tak (tekking og lufting) | D36: 22×148 furu | E36: lm | F36: 8 | G36: 10 | H36: =ROUND(F36*(1+G36/100),1) -> 8.8 | I36: 70 | J36: =ROUND(H36*I36,0) -> 616 | K36: Ventilasjonsåpning foran
A37: 35 | B37: Insektnett (ventilasjon tak) | C37: 5. Tak (tekking og lufting) | D37: Ved takfot bak og øvre takkant | E37: lm | F37: 20 | G37: 10 | H37: =ROUND(F37*(1+G37/100),1) -> 22 | I37: 35 | J37: =ROUND(H37*I37,0) -> 770 | K37: Mygg-/insektsnett 100 mm
A38: 36 | B38: Vindsperre 9 mm vindtettplate | C38: 6. Utv. kledning og lufting | D38: Evt. diffusjonsåpen duk | E38: m² | F38: 35 | G38: 15 | H38: =ROUND(F38*(1+G38/100),1) -> 40.3 | I38: 95 | J38: =ROUND(H38*I38,0) -> 3829 | K38: Over stendere
A39: 37 | B39: Klimaspalte-lekter 23×48 | C39: 6. Utv. kledning og lufting | D39: Horisontale (pga stående panel) | E39: lm | F39: 60 | G39: 10 | H39: =ROUND(F39*(1+G39/100),1) -> 66 | I39: 22 | J39: =ROUND(H39*I39,0) -> 1452
A40: 38 | B40: Stående tømmermannspanel 22×120 (underbord) | C40: 6. Utv. kledning og lufting | D40: Furu, impregnert el. malt | E40: lm | F40: 230 | G40: 10 | H40: =ROUND(F40*(1+G40/100),1) -> 253 | I40: 55 | J40: =ROUND(H40*I40,0) -> 13915 | K40: Yttervegg + nordvegg overbygg
...

Sheet Beregninger
A1: STATISKE BEREGNINGER
A3: TAKBJELKER 48×148 C24 (c/c 500)
A4: Spenn | B4: 2,46 m
A5: Snølast | B5: 450 kg/m² = 4,41 kN/m²
A6: Last pr bjelke (c/c 0,5 m) | B6: 2,21 kN/m
A7: Moment M = wL²/8 | B7: 1,67 kNm
A8: Moment-kapasitet M_Rd (C24, k_mod=0,9) | B8: 2,91 kNm
A9: Utnyttelse | B9: 57 %
A10: Nedbøyning δ = 5wL⁴/(384EI) | B10: 4,5 mm
A11: Krav L/300 | B11: 8,2 mm
A12: Status | B12: OK
A14: SYDBJELKE OVERBYGG (fritt spenn 3 m)
A15: Last på bjelke | B15: 5,43 kN/m
A16: Moment M = wL²/8 | B16: 6,11 kNm
A17: 1 × 48×198 M_Rd | B17: 5,21 kNm
A18: 2 × 48×198 koblet M_Rd | B18: 10,4 kNm
A19: Nedbøyning (2×48×198) | B19: 8,3 mm
A20: Status 2×48×198 | B20: OK
A22: FUNDAMENT
A23: Egenvekt bygg | B23: ~3,8 t
A24: Snølast på hele taket | B24: ~5,2 t
A25: Nyttelast | B25: 0,5 t
A26: Total dim. last | B26: 9,6 t = 94 kN
A27: Antall sokler | B27: 6
A28: Last pr sokkel | B28: ~16 kN (dim. 25 kN m/ sikkerhet)
A29: Sokkel-dimensjon | B29: 250×250×1800 + plate 500×500×200
A30: Fundamentdybde | B30: 1,8–2,0 m under terreng (telefri)
A32: BADSTUEOVN
A33: Grunnvolum | B33: 8,73 m³
A34: Vindu-tillegg (0,9 m² × 1,5) | B34: 1,35 m³
A35: Dør-tillegg | B35: 0,33 m³
A36: Effektivt volum | B36: 10,41 m³
A37: Minimum effekt (1,0 kW/m³) | B37: 10,4 kW
A38: Anbefalt (1,1 kW/m³) | B38: 11,0 kW
A39: Rask oppvarming (1,3 kW/m³) | B39: 13,5 kW

Sheet Budsjettvariant
A1: BUDSJETTVARIANT — i to trinn
A2: Rimeligere materialvalg, merket med hvilket byggetrinn de hører til.
A3: Vinduer, dører og fundamenter har du allerede — holdt utenfor (kostnad 0).
A4: Reisverk, isolasjon, dampsperre, vindsperre og lufting er IKKE rørt.
A6: Post | B6: Trinn | C6: Standard-valg | D6: Standard kr | E6: Budsjett-valg | F6: Budsjett kr | G6: Spart kr
A7: Taktekking | B7: Trinn 1 | C7: Asfalt-shingel + taktro 22 mm + bitumen-papp | D7: 19390 | E7: Ståltak (profilerte plater) på lekter — taktro utgår | F7: 11800 | G7: =D7-F7 -> 7590
A8: Utvendig kledning | B8: Trinn 1 | C8: Stående tømmermannspanel (2-lags) + 2 strøk maling | D8: 29080 | E8: Royalimpregnert dobbeltfals stående panel (1-lag) | F8: 14440 | G8: =D8-F8 -> 14640
A9: Innv. panel badstue | B9: Trinn 2 | C9: Osp-panel 22 m² (~420 kr/m²) | D9: 10626 | E9: Varmebehandlet furu-panel (osp beholdes på benkene) | F9: 5566 | G9: =D9-F9 -> 5060
A10: Badstueovn | B10: Trinn 2 | C10: Plassholder (kvalitetsovn) | D10: 9000 | E10: Standard elektrisk 11 kW (f.eks. Harvia Vega) | F10: 6000 | G10: =D10-F10 -> 3000
A11: Gulvrist + belysning | B11: Trinn 2 | C11: Gulvrist sedertre + LED-armatursett | D11: 2150 | E11: Enkel gulvrist + enklere armatur | F11: 1100 | G11: =D11-F11 -> 1050
A12: SUM ENDRINGER | D12: =SUM(D7:D11) -> 70246 | F12: =SUM(F7:F11) -> 38906 | G12: =SUM(G7:G11) -> 31340
A14: KOSTNADSMATRISE — variant × trinn (eks. mva)
B15: Trinn 1 (uten badstue-innredning) | D15: Trinn 2 (innredning badstuerom) | F15: Totalt (helt ferdig)
A16: Standard | B16: =Materialliste!J80-Prosjektfaser!C21 -> 116909 | D16: =Prosjektfaser!C21 -> 37449 | F16: =Materialliste!J80 -> 154358
A17: Budsjett | B17: =B16-SUMIF(B7:B11,"Trinn 1",G7:G11) -> 94679 | D17: =D16-SUMIF(B7:B11,"Trinn 2",G7:G11) -> 28339 | F17: =B17+D17 -> 123018
A18: Besparelse | B18: =B16-B17 -> 22230 | D18: =D16-D17 -> 9110 | F18: =F16-F17 -> 31340
A19: Budsjett inkl. mva 25 % | B19: =B17*1.25 -> 118348.75 | D19: =D17*1.25 -> 35423.75 | F19: =F17*1.25 -> 153772.5
A21: Slik leser du matrisen:
A22: • Vil du bygge billigst mulig nå og utsette badstuerommet: se "Budsjett / Trinn 1".
A23: • Trinn 1 + Trinn 2 i en kolonne summerer alltid til "Totalt" i samme rad.
A24: • Standard Trinn 1 / Trinn 2 hentes automatisk fra arket "Prosjektfaser".
A25: • Ståltak og kledning er trinn 1-tiltak; ovn, badstuepanel og gulvrist/lys er trinn 2.
A26: • Reisverk, fundament, isolasjon, dampsperre, vindsperre og lufting er beholdt uendret i begge varianter.
